[2025-04-12T10:57:49.934+0000] {taskinstance.py:1956} INFO - Dependencies all met for dep_context=non-requeueable deps ti=<TaskInstance: crawl_data_to_hdfs.run_real_estate_crawler manual__2025-04-12T10:57:48.732116+00:00 [queued]>
[2025-04-12T10:57:49.942+0000] {taskinstance.py:1956} INFO - Dependencies all met for dep_context=requeueable deps ti=<TaskInstance: crawl_data_to_hdfs.run_real_estate_crawler manual__2025-04-12T10:57:48.732116+00:00 [queued]>
[2025-04-12T10:57:49.943+0000] {taskinstance.py:2170} INFO - Starting attempt 1 of 2
[2025-04-12T10:57:49.953+0000] {taskinstance.py:2191} INFO - Executing <Task(DockerOperator): run_real_estate_crawler> on 2025-04-12 10:57:48.732116+00:00
[2025-04-12T10:57:49.959+0000] {standard_task_runner.py:60} INFO - Started process 183 to run task
[2025-04-12T10:57:49.965+0000] {standard_task_runner.py:87} INFO - Running: ['***', 'tasks', 'run', 'crawl_data_to_hdfs', 'run_real_estate_crawler', 'manual__2025-04-12T10:57:48.732116+00:00', '--job-id', '18', '--raw', '--subdir', 'DAGS_FOLDER/crawl_data_dag.py', '--cfg-path', '/tmp/tmptld8jqpu']
[2025-04-12T10:57:49.969+0000] {standard_task_runner.py:88} INFO - Job 18: Subtask run_real_estate_crawler
[2025-04-12T10:57:49.983+0000] {logging_mixin.py:188} WARNING - /home/***/.local/lib/python3.8/site-packages/***/settings.py:194 DeprecationWarning: The sql_alchemy_conn option in [core] has been moved to the sql_alchemy_conn option in [database] - the old setting has been used, but please update your config.
[2025-04-12T10:57:50.015+0000] {task_command.py:423} INFO - Running <TaskInstance: crawl_data_to_hdfs.run_real_estate_crawler manual__2025-04-12T10:57:48.732116+00:00 [running]> on host 0b19cf2a3606
[2025-04-12T10:57:50.083+0000] {taskinstance.py:2480} INFO - Exporting env vars: AIRFLOW_CTX_DAG_OWNER='***' AIRFLOW_CTX_DAG_ID='crawl_data_to_hdfs' AIRFLOW_CTX_TASK_ID='run_real_estate_crawler' AIRFLOW_CTX_EXECUTION_DATE='2025-04-12T10:57:48.732116+00:00' AIRFLOW_CTX_TRY_NUMBER='1' AIRFLOW_CTX_DAG_RUN_ID='manual__2025-04-12T10:57:48.732116+00:00'
[2025-04-12T10:57:50.096+0000] {docker.py:359} INFO - Starting docker container from image realestate-crawler
[2025-04-12T10:57:50.099+0000] {docker.py:367} WARNING - Using remote engine or docker-in-docker and mounting temporary volume from host is not supported. Falling back to `mount_tmp_dir=False` mode. You can set `mount_tmp_dir` parameter to False to disable mounting and remove the warning
[2025-04-12T10:57:50.266+0000] {taskinstance.py:2698} ERROR - Task failed with exception
Traceback (most recent call last):
  File "/home/airflow/.local/lib/python3.8/site-packages/docker/api/client.py", line 265, in _raise_for_status
    response.raise_for_status()
  File "/home/airflow/.local/lib/python3.8/site-packages/requests/models.py", line 1021, in raise_for_status
    raise HTTPError(http_error_msg, response=self)
requests.exceptions.HTTPError: 400 Client Error: Bad Request for url: http+docker://localhost/v1.48/containers/create?name=***-crawler-task

The above exception was the direct cause of the following exception:

Traceback (most recent call last):
  File "/home/airflow/.local/lib/python3.8/site-packages/airflow/providers/docker/operators/docker.py", line 364, in _run_image
    return self._run_image_with_mounts([*self.mounts, tmp_mount], add_tmp_variable=True)
  File "/home/airflow/.local/lib/python3.8/site-packages/airflow/providers/docker/operators/docker.py", line 391, in _run_image_with_mounts
    self.container = self.cli.create_container(
  File "/home/airflow/.local/lib/python3.8/site-packages/docker/api/container.py", line 439, in create_container
    return self.create_container_from_config(config, name, platform)
  File "/home/airflow/.local/lib/python3.8/site-packages/docker/api/container.py", line 456, in create_container_from_config
    return self._result(res, True)
  File "/home/airflow/.local/lib/python3.8/site-packages/docker/api/client.py", line 271, in _result
    self._raise_for_status(response)
  File "/home/airflow/.local/lib/python3.8/site-packages/docker/api/client.py", line 267, in _raise_for_status
    raise create_api_error_from_http_exception(e) from e
  File "/home/airflow/.local/lib/python3.8/site-packages/docker/errors.py", line 39, in create_api_error_from_http_exception
    raise cls(e, response=response, explanation=explanation) from e
docker.errors.APIError: 400 Client Error for http+docker://localhost/v1.48/containers/create?name=airflow-crawler-task: Bad Request ("invalid mount config for type "bind": bind source path does not exist: /tmp/airflowtmpiut4ecb0")

During handling of the above exception, another exception occurred:

Traceback (most recent call last):
  File "/home/airflow/.local/lib/python3.8/site-packages/docker/api/client.py", line 265, in _raise_for_status
    response.raise_for_status()
  File "/home/airflow/.local/lib/python3.8/site-packages/requests/models.py", line 1021, in raise_for_status
    raise HTTPError(http_error_msg, response=self)
requests.exceptions.HTTPError: 404 Client Error: Not Found for url: http+docker://localhost/v1.48/containers/53e09f039e28f708b2479dc90041a18ec5bed7d458d50f0445f3af43ec05e1a6/start

The above exception was the direct cause of the following exception:

Traceback (most recent call last):
  File "/home/airflow/.local/lib/python3.8/site-packages/airflow/models/taskinstance.py", line 433, in _execute_task
    result = execute_callable(context=context, **execute_callable_kwargs)
  File "/home/airflow/.local/lib/python3.8/site-packages/airflow/providers/docker/operators/docker.py", line 502, in execute
    return self._run_image()
  File "/home/airflow/.local/lib/python3.8/site-packages/airflow/providers/docker/operators/docker.py", line 373, in _run_image
    return self._run_image_with_mounts(self.mounts, add_tmp_variable=False)
  File "/home/airflow/.local/lib/python3.8/site-packages/airflow/providers/docker/operators/docker.py", line 423, in _run_image_with_mounts
    self.cli.start(self.container["Id"])
  File "/home/airflow/.local/lib/python3.8/site-packages/docker/utils/decorators.py", line 19, in wrapped
    return f(self, resource_id, *args, **kwargs)
  File "/home/airflow/.local/lib/python3.8/site-packages/docker/api/container.py", line 1135, in start
    self._raise_for_status(res)
  File "/home/airflow/.local/lib/python3.8/site-packages/docker/api/client.py", line 267, in _raise_for_status
    raise create_api_error_from_http_exception(e) from e
  File "/home/airflow/.local/lib/python3.8/site-packages/docker/errors.py", line 39, in create_api_error_from_http_exception
    raise cls(e, response=response, explanation=explanation) from e
docker.errors.NotFound: 404 Client Error for http+docker://localhost/v1.48/containers/53e09f039e28f708b2479dc90041a18ec5bed7d458d50f0445f3af43ec05e1a6/start: Not Found ("failed to set up container networking: network hdfs_network not found")
[2025-04-12T10:57:50.275+0000] {taskinstance.py:1138} INFO - Marking task as UP_FOR_RETRY. dag_id=crawl_data_to_hdfs, task_id=run_real_estate_crawler, execution_date=20250412T105748, start_date=20250412T105749, end_date=20250412T105750
[2025-04-12T10:57:50.287+0000] {standard_task_runner.py:107} ERROR - Failed to execute job 18 for task run_real_estate_crawler (404 Client Error for http+docker://localhost/v1.48/containers/53e09f039e28f708b2479dc90041a18ec5bed7d458d50f0445f3af43ec05e1a6/start: Not Found ("failed to set up container networking: network hdfs_network not found"); 183)
[2025-04-12T10:57:50.334+0000] {local_task_job_runner.py:234} INFO - Task exited with return code 1
[2025-04-12T10:57:50.357+0000] {taskinstance.py:3280} INFO - 0 downstream tasks scheduled from follow-on schedule check
