[2025-04-12T10:32:07.091+0000] {taskinstance.py:1956} INFO - Dependencies all met for dep_context=non-requeueable deps ti=<TaskInstance: crawl_data_to_hdfs.run_real_estate_crawler manual__2025-04-12T10:27:05.244325+00:00 [queued]>
[2025-04-12T10:32:07.098+0000] {taskinstance.py:1956} INFO - Dependencies all met for dep_context=requeueable deps ti=<TaskInstance: crawl_data_to_hdfs.run_real_estate_crawler manual__2025-04-12T10:27:05.244325+00:00 [queued]>
[2025-04-12T10:32:07.098+0000] {taskinstance.py:2170} INFO - Starting attempt 2 of 2
[2025-04-12T10:32:07.109+0000] {taskinstance.py:2191} INFO - Executing <Task(DockerOperator): run_real_estate_crawler> on 2025-04-12 10:27:05.244325+00:00
[2025-04-12T10:32:07.115+0000] {standard_task_runner.py:60} INFO - Started process 311 to run task
[2025-04-12T10:32:07.121+0000] {standard_task_runner.py:87} INFO - Running: ['***', 'tasks', 'run', 'crawl_data_to_hdfs', 'run_real_estate_crawler', 'manual__2025-04-12T10:27:05.244325+00:00', '--job-id', '9', '--raw', '--subdir', 'DAGS_FOLDER/crawl_data_dag.py', '--cfg-path', '/tmp/tmpp3e0nmd2']
[2025-04-12T10:32:07.125+0000] {standard_task_runner.py:88} INFO - Job 9: Subtask run_real_estate_crawler
[2025-04-12T10:32:07.139+0000] {logging_mixin.py:188} WARNING - /home/***/.local/lib/python3.8/site-packages/***/settings.py:194 DeprecationWarning: The sql_alchemy_conn option in [core] has been moved to the sql_alchemy_conn option in [database] - the old setting has been used, but please update your config.
[2025-04-12T10:32:07.172+0000] {task_command.py:423} INFO - Running <TaskInstance: crawl_data_to_hdfs.run_real_estate_crawler manual__2025-04-12T10:27:05.244325+00:00 [running]> on host 7d2e9de5d1c0
[2025-04-12T10:32:07.247+0000] {taskinstance.py:2480} INFO - Exporting env vars: AIRFLOW_CTX_DAG_OWNER='***' AIRFLOW_CTX_DAG_ID='crawl_data_to_hdfs' AIRFLOW_CTX_TASK_ID='run_real_estate_crawler' AIRFLOW_CTX_EXECUTION_DATE='2025-04-12T10:27:05.244325+00:00' AIRFLOW_CTX_TRY_NUMBER='2' AIRFLOW_CTX_DAG_RUN_ID='manual__2025-04-12T10:27:05.244325+00:00'
[2025-04-12T10:32:07.250+0000] {taskinstance.py:2698} ERROR - Task failed with exception
Traceback (most recent call last):
  File "/home/airflow/.local/lib/python3.8/site-packages/urllib3/connectionpool.py", line 715, in urlopen
    httplib_response = self._make_request(
  File "/home/airflow/.local/lib/python3.8/site-packages/urllib3/connectionpool.py", line 416, in _make_request
    conn.request(method, url, **httplib_request_kw)
  File "/home/airflow/.local/lib/python3.8/site-packages/urllib3/connection.py", line 244, in request
    super(HTTPConnection, self).request(method, url, body=body, headers=headers)
  File "/usr/local/lib/python3.8/http/client.py", line 1256, in request
    self._send_request(method, url, body, headers, encode_chunked)
  File "/usr/local/lib/python3.8/http/client.py", line 1302, in _send_request
    self.endheaders(body, encode_chunked=encode_chunked)
  File "/usr/local/lib/python3.8/http/client.py", line 1251, in endheaders
    self._send_output(message_body, encode_chunked=encode_chunked)
  File "/usr/local/lib/python3.8/http/client.py", line 1011, in _send_output
    self.send(msg)
  File "/usr/local/lib/python3.8/http/client.py", line 951, in send
    self.connect()
  File "/home/airflow/.local/lib/python3.8/site-packages/docker/transport/unixconn.py", line 27, in connect
    sock.connect(self.unix_socket)
FileNotFoundError: [Errno 2] No such file or directory

During handling of the above exception, another exception occurred:

Traceback (most recent call last):
  File "/home/airflow/.local/lib/python3.8/site-packages/requests/adapters.py", line 486, in send
    resp = conn.urlopen(
  File "/home/airflow/.local/lib/python3.8/site-packages/urllib3/connectionpool.py", line 799, in urlopen
    retries = retries.increment(
  File "/home/airflow/.local/lib/python3.8/site-packages/urllib3/util/retry.py", line 550, in increment
    raise six.reraise(type(error), error, _stacktrace)
  File "/home/airflow/.local/lib/python3.8/site-packages/urllib3/packages/six.py", line 769, in reraise
    raise value.with_traceback(tb)
  File "/home/airflow/.local/lib/python3.8/site-packages/urllib3/connectionpool.py", line 715, in urlopen
    httplib_response = self._make_request(
  File "/home/airflow/.local/lib/python3.8/site-packages/urllib3/connectionpool.py", line 416, in _make_request
    conn.request(method, url, **httplib_request_kw)
  File "/home/airflow/.local/lib/python3.8/site-packages/urllib3/connection.py", line 244, in request
    super(HTTPConnection, self).request(method, url, body=body, headers=headers)
  File "/usr/local/lib/python3.8/http/client.py", line 1256, in request
    self._send_request(method, url, body, headers, encode_chunked)
  File "/usr/local/lib/python3.8/http/client.py", line 1302, in _send_request
    self.endheaders(body, encode_chunked=encode_chunked)
  File "/usr/local/lib/python3.8/http/client.py", line 1251, in endheaders
    self._send_output(message_body, encode_chunked=encode_chunked)
  File "/usr/local/lib/python3.8/http/client.py", line 1011, in _send_output
    self.send(msg)
  File "/usr/local/lib/python3.8/http/client.py", line 951, in send
    self.connect()
  File "/home/airflow/.local/lib/python3.8/site-packages/docker/transport/unixconn.py", line 27, in connect
    sock.connect(self.unix_socket)
urllib3.exceptions.ProtocolError: ('Connection aborted.', FileNotFoundError(2, 'No such file or directory'))

During handling of the above exception, another exception occurred:

Traceback (most recent call last):
  File "/home/airflow/.local/lib/python3.8/site-packages/docker/api/client.py", line 213, in _retrieve_server_version
    return self.version(api_version=False)["ApiVersion"]
  File "/home/airflow/.local/lib/python3.8/site-packages/docker/api/daemon.py", line 181, in version
    return self._result(self._get(url), json=True)
  File "/home/airflow/.local/lib/python3.8/site-packages/docker/utils/decorators.py", line 44, in inner
    return f(self, *args, **kwargs)
  File "/home/airflow/.local/lib/python3.8/site-packages/docker/api/client.py", line 236, in _get
    return self.get(url, **self._set_request_timeout(kwargs))
  File "/home/airflow/.local/lib/python3.8/site-packages/requests/sessions.py", line 602, in get
    return self.request("GET", url, **kwargs)
  File "/home/airflow/.local/lib/python3.8/site-packages/requests/sessions.py", line 589, in request
    resp = self.send(prep, **send_kwargs)
  File "/home/airflow/.local/lib/python3.8/site-packages/requests/sessions.py", line 703, in send
    r = adapter.send(request, **kwargs)
  File "/home/airflow/.local/lib/python3.8/site-packages/requests/adapters.py", line 501, in send
    raise ConnectionError(err, request=request)
requests.exceptions.ConnectionError: ('Connection aborted.', FileNotFoundError(2, 'No such file or directory'))

The above exception was the direct cause of the following exception:

Traceback (most recent call last):
  File "/home/airflow/.local/lib/python3.8/site-packages/airflow/models/taskinstance.py", line 433, in _execute_task
    result = execute_callable(context=context, **execute_callable_kwargs)
  File "/home/airflow/.local/lib/python3.8/site-packages/airflow/providers/docker/operators/docker.py", line 485, in execute
    if self.force_pull or not self.cli.images(name=self.image):
  File "/home/airflow/.local/lib/python3.8/site-packages/airflow/providers/docker/operators/docker.py", line 355, in cli
    return self.hook.api_client
  File "/usr/local/lib/python3.8/functools.py", line 967, in __get__
    val = self.func(instance)
  File "/home/airflow/.local/lib/python3.8/site-packages/airflow/providers/docker/hooks/docker.py", line 120, in api_client
    client = APIClient(
  File "/home/airflow/.local/lib/python3.8/site-packages/docker/api/client.py", line 197, in __init__
    self._version = self._retrieve_server_version()
  File "/home/airflow/.local/lib/python3.8/site-packages/docker/api/client.py", line 220, in _retrieve_server_version
    raise DockerException(
docker.errors.DockerException: Error while fetching server API version: ('Connection aborted.', FileNotFoundError(2, 'No such file or directory'))
[2025-04-12T10:32:07.259+0000] {taskinstance.py:1138} INFO - Marking task as FAILED. dag_id=crawl_data_to_hdfs, task_id=run_real_estate_crawler, execution_date=20250412T102705, start_date=20250412T103207, end_date=20250412T103207
[2025-04-12T10:32:07.268+0000] {standard_task_runner.py:107} ERROR - Failed to execute job 9 for task run_real_estate_crawler (Error while fetching server API version: ('Connection aborted.', FileNotFoundError(2, 'No such file or directory')); 311)
[2025-04-12T10:32:07.290+0000] {local_task_job_runner.py:234} INFO - Task exited with return code 1
[2025-04-12T10:32:07.313+0000] {taskinstance.py:3280} INFO - 0 downstream tasks scheduled from follow-on schedule check
